<?xml version="1.0" ?>
<!-- =================================================================================== -->
<!-- |    This document was autogenerated by xacro from open_manipulator_robot.urdf.xacro | -->
<!-- |    EDITING THIS FILE BY HAND IS NOT RECOMMENDED                                 | -->
<!-- =================================================================================== -->
<!-- Open_Manipulator Chain -->
<!-- Inertial properties updated from measured masses (balance) + Autodesk Inventor CAD -->
<!-- Per-link masses measured physically; inertia tensors computed in Inventor at CoG,  -->
<!-- then scaled by ratio m_measured/m_CAD. CoG and tensors expressed in URDF frame.    -->
<robot name="open_manipulator">
  <material name="black">
    <color rgba="0.0 0.0 0.0 1.0"/>
  </material>
  <material name="white">
    <color rgba="1.0 1.0 1.0 1.0"/>
  </material>
  <material name="red">
    <color rgba="0.8 0.0 0.0 1.0"/>
  </material>
  <material name="blue">
    <color rgba="0.0 0.0 0.8 1.0"/>
  </material>
  <material name="green">
    <color rgba="0.0 0.8 0.0 1.0"/>
  </material>
  <material name="grey">
    <color rgba="0.5 0.5 0.5 1.0"/>
  </material>
  <material name="orange">
    <color rgba="1.0 0.4235294117647059 0.0392156862745098 1.0"/>
  </material>
  <material name="brown">
    <color rgba="0.8705882352941177 0.8117647058823529 0.7647058823529411 1.0"/>
  </material>
  <!-- World -->
  <gazebo reference="world"/>
  <!-- Link1 -->
  <RefLink ref="link1"/>
  <!-- Link2 -->
  <RefLink ref="link2"/>
  <!-- Link3 -->
  <RefLink ref="link3"/>
  <!-- Link4 -->
  <RefLink ref="link4"/>
  <!-- Link5 -->
  <RefLink ref="link5"/>
  <!-- gripper_link -->
  <RefLink ref="gripper_link"/>
  <!-- gripper_link_sub -->
  <RefLink ref="gripper_link_sub"/>
  <!-- end effector link -->
  <gazebo reference="end_effector_link">
    <material>Gazebo/Red</material>
  </gazebo>
  <!-- ros_control plugin -->
  <gazebo>
    <plugin filename="libgazebo_ros_control.so" name="gazebo_ros_control">
      <controlPeriod>0.001</controlPeriod>
      <robotSimType>gazebo_ros_control/DefaultRobotHWSim</robotSimType>
      <legacyModeNS>true</legacyModeNS>
    </plugin>
  </gazebo>
  <gazebo>
    <!-- loading plugin: mimic joints works in gazebo now -->
    <plugin filename="libroboticsgroup_gazebo_mimic_joint_plugin.so" name="gazebo_gripper_ros_control">
      <joint>gripper</joint>
      <mimicJoint>gripper_sub</mimicJoint>
      <multiplier>1.0</multiplier>
      <offset>0.0</offset>
    </plugin>
  </gazebo>
  <!-- camera -->
  <gazebo reference="camera_link">
    <sensor name="intel_realsense_r200" type="camera">
      <update_rate>30.0</update_rate>
      <camera name="head">
        <horizontal_fov>1.02974</horizontal_fov>
        <image>
          <width>1920</width>
          <height>1080</height>
          <format>R8G8B8</format>
        </image>
        <clip>
          <near>0.02</near>
          <far>300</far>
        </clip>
        <noise>
          <type>gaussian</type>
          <!-- Noise is sampled independently per pixel on each frame.
               That pixel's noise value is added to each of its color
               channels, which at that point lie in the range [0,1]. -->
          <mean>0.0</mean>
          <stddev>0.007</stddev>
        </noise>
      </camera>
      <plugin filename="libgazebo_ros_camera.so" name="camera_controller">
        <alwaysOn>true</alwaysOn>
        <updateRate>0.0</updateRate>
        <cameraName>camera/color</cameraName>
        <imageTopicName>image_raw</imageTopicName>
        <cameraInfoTopicName>camera_info</cameraInfoTopicName>
        <frameName>camera_link</frameName>
        <hackBaseline>0.07</hackBaseline>
        <distortionK1>0.0</distortionK1>
        <distortionK2>0.0</distortionK2>
        <distortionK3>0.0</distortionK3>
        <distortionT1>0.0</distortionT1>
        <distortionT2>0.0</distortionT2>
      </plugin>
    </sensor>
  </gazebo>
  <transmission name="tran1">
    <type>transmission_interface/SimpleTransmission</type>
    <joint name="joint1">
      <hardwareInterface>hardware_interface/PositionJointInterface</hardwareInterface>
    </joint>
    <actuator name="motor1">
      <mechanicalReduction>1</mechanicalReduction>
    </actuator>
  </transmission>
  <transmission name="tran2">
    <type>transmission_interface/SimpleTransmission</type>
    <joint name="joint2">
      <hardwareInterface>hardware_interface/PositionJointInterface</hardwareInterface>
    </joint>
    <actuator name="motor2">
      <mechanicalReduction>1</mechanicalReduction>
    </actuator>
  </transmission>
  <transmission name="tran3">
    <type>transmission_interface/SimpleTransmission</type>
    <joint name="joint3">
      <hardwareInterface>hardware_interface/PositionJointInterface</hardwareInterface>
    </joint>
    <actuator name="motor3">
      <mechanicalReduction>1</mechanicalReduction>
    </actuator>
  </transmission>
  <transmission name="tran4">
    <type>transmission_interface/SimpleTransmission</type>
    <joint name="joint4">
      <hardwareInterface>hardware_interface/PositionJointInterface</hardwareInterface>
    </joint>
    <actuator name="motor4">
      <mechanicalReduction>1</mechanicalReduction>
    </actuator>
  </transmission>
  <transmission name="tran5">
    <type>transmission_interface/SimpleTransmission</type>
    <joint name="gripper">
      <hardwareInterface>hardware_interface/EffortJointInterface</hardwareInterface>
    </joint>
    <actuator name="motor5">
      <mechanicalReduction>1</mechanicalReduction>
    </actuator>
  </transmission>
  <transmission name="tran6">
    <type>transmission_interface/SimpleTransmission</type>
    <joint name="gripper_sub">
      <hardwareInterface>hardware_interface/EffortJointInterface</hardwareInterface>
    </joint>
    <actuator name="motor6">
      <mechanicalReduction>1</mechanicalReduction>
    </actuator>
  </transmission>
  <!-- Link 1 -->
  <link name="link1">
    <visual>
      <origin rpy="0 0 0" xyz="0 0 0"/>
      <geometry>
        <mesh filename="package://open_manipulator_description/meshes/chain_link1.stl" scale="0.001 0.001 0.001"/>
      </geometry>
      <material name="grey"/>
    </visual>
    <collision>
      <origin rpy="0 0 0" xyz="0 0 0"/>
      <geometry>
        <mesh filename="package://open_manipulator_description/meshes/chain_link1.stl" scale="0.001 0.001 0.001"/>
      </geometry>
    </collision>
    <inertial>
      <origin xyz="0.000308 0.000000 0.017927" rpy="0 0 0"/>
      <mass value="0.0804"/>
      <inertia ixx="1.275713e-05" ixy="0.000000e+00" ixz="-1.794293e-07" iyy="2.234728e-05" iyz="0.000000e+00" izz="1.965878e-05"/>
    </inertial>
  </link>
  <!-- Joint 1 -->
  <joint name="joint1" type="revolute">
    <parent link="link1"/>
    <child link="link2"/>
    <origin rpy="0 0 0" xyz="0.012 0.0 0.017"/>
    <axis xyz="0 0 1"/>
    <limit effort="1" lower="-2.356194490192345" upper="2.356194490192345" velocity="4.8"/>
    <dynamics damping="0.0230" friction="0.0168"/>
  </joint>
  <!--  Link 2 -->
  <link name="link2">
    <visual>
      <origin rpy="0 0 0" xyz="0 0 0.019"/>
      <geometry>
        <mesh filename="package://open_manipulator_description/meshes/chain_link2.stl" scale="0.001 0.001 0.001"/>
      </geometry>
      <material name="grey"/>
    </visual>
    <collision>
      <origin rpy="0 0 0" xyz="0 0 0.019"/>
      <geometry>
        <mesh filename="package://open_manipulator_description/meshes/chain_link2.stl" scale="0.001 0.001 0.001"/>
      </geometry>
    </collision>
    <!-- Updated from ROBOTIS e-Manual inertial data, using mass/CoG/Inertia Tensor at CENTER OF GRAVITY, transformed from C1 frame to URDF link frame. R = I (no rotation). -->
    <inertial>
      <origin xyz="0.000000 0.000657 0.044319" rpy="0 0 0"/>
      <mass value="0.0970"/>
      <inertia ixx="3.078317e-05" ixy="0.000000e+00" ixz="0.000000e+00" iyy="2.670366e-05" iyz="-1.289659e-07" izz="1.627175e-05"/>
    </inertial>
  </link>
  <!--  Joint 2 -->
  <joint name="joint2" type="revolute">
    <parent link="link2"/>
    <child link="link3"/>
    <origin rpy="0 0 0" xyz="0.0 0.0 0.0595"/>
    <axis xyz="0 1 0"/>
    <limit effort="1" lower="-1.9198621771937625" upper="1.7453292519943295" velocity="4.8"/>
    <dynamics damping="0.0194" friction="0.0089"/>
  </joint>
  <!--  Link 3 -->
  <link name="link3">
    <visual>
      <origin rpy="0 0 0" xyz="0 0 0"/>
      <geometry>
        <mesh filename="package://open_manipulator_description/meshes/chain_link3.stl" scale="0.001 0.001 0.001"/>
      </geometry>
      <material name="grey"/>
    </visual>
    <collision>
      <origin rpy="0 0 0" xyz="0 0 0"/>
      <geometry>
        <mesh filename="package://open_manipulator_description/meshes/chain_link3.stl" scale="0.001 0.001 0.001"/>
      </geometry>
    </collision>
    <!-- Updated from ROBOTIS e-Manual inertial data, using mass/CoG/Inertia Tensor at CENTER OF GRAVITY, transformed from C2 frame to URDF link frame. R = Rz(180deg): r_urdf=(-x,-y,z); Ixz->-Ixz, Iyz->-Iyz. -->
    <inertial>
      <origin xyz="0.007606 0.000389 0.099924" rpy="0 0 0"/>
      <mass value="0.1235"/>
      <inertia ixx="1.979680e-04" ixy="-2.511443e-07" ixz="-2.497601e-05" iyy="2.046627e-04" iyz="-1.351040e-06" izz="3.374865e-05"/>
    </inertial>
  </link>
  <!--  Joint 3 -->
  <joint name="joint3" type="revolute">
    <parent link="link3"/>
    <child link="link4"/>
    <origin rpy="0 0 0" xyz="0.024 0 0.128"/>
    <axis xyz="0 1 0"/>
    <limit effort="1" lower="-1.9198621771937625" upper="1.5707963267948966" velocity="4.8"/>
    <dynamics damping="0.0229" friction="0.0094"/>
  </joint>
  <!--  Link 4 -->
  <link name="link4">
    <visual>
      <origin rpy="0 0 0" xyz="0 0 0"/>
      <geometry>
        <mesh filename="package://open_manipulator_description/meshes/chain_link4.stl" scale="0.001 0.001 0.001"/>
      </geometry>
      <material name="grey"/>
    </visual>
    <collision>
      <origin rpy="0 0 0" xyz="0 0 0"/>
      <geometry>
        <mesh filename="package://open_manipulator_description/meshes/chain_link4.stl" scale="0.001 0.001 0.001"/>
      </geometry>
    </collision>
    <!-- Updated from ROBOTIS e-Manual inertial data, using mass/CoG/Inertia Tensor at CENTER OF GRAVITY, transformed from C3 frame to URDF link frame. R = R_alt: C3_z->URDF_x, C3_y->-URDF_y, C3_x->+URDF_z; I_urdf=[Izz,-Iyz,Ixz; -Iyz,Iyy,-Ixy; Ixz,-Ixy,Ixx]. -->
    <inertial>
      <origin xyz="0.089168 0.000437 0.000001" rpy="0 0 0"/>
      <mass value="0.1151"/>
      <inertia ixx="1.930305e-05" ixy="-1.189078e-06" ixz="3.461654e-09" iyy="1.483284e-04" iyz="0.000000e+00" izz="1.547550e-04"/>
    </inertial>
  </link>
  <!--  Joint 4 -->
  <joint name="joint4" type="revolute">
    <parent link="link4"/>
    <child link="link5"/>
    <origin rpy="0 0 0" xyz="0.124 0.0 0.0"/>
    <axis xyz="0 1 0"/>
    <limit effort="1" lower="-1.8" upper="2.1" velocity="4.8"/>
    <dynamics damping="0.0158" friction="0.0377"/>
  </joint>
  <!--  Link 5 -->
  <link name="link5">
    <visual>
      <origin rpy="0 0 0" xyz="0 0 0"/>
      <geometry>
        <mesh filename="package://open_manipulator_description/meshes/chain_link5.stl" scale="0.001 0.001 0.001"/>
      </geometry>
      <material name="grey"/>
    </visual>
    <collision>
      <origin rpy="0 0 0" xyz="0 0 0"/>
      <geometry>
        <mesh filename="package://open_manipulator_description/meshes/chain_link5.stl" scale="0.001 0.001 0.001"/>
      </geometry>
    </collision>
    <!-- Updated from ROBOTIS e-Manual inertial data, using mass/CoG/Inertia Tensor at CENTER OF GRAVITY, transformed from C4 frame to URDF link frame. R = R_alt: C4_z->URDF_x, C4_y->-URDF_y, C4_x->+URDF_z; I_urdf=[Izz,-Iyz,Ixz; -Iyz,Iyy,-Ixy; Ixz,-Ixy,Ixx]. -->
    <inertial>
      <origin xyz="0.062451 0.000000 0.005878" rpy="0 0 0"/>
      <mass value="0.2206"/>
      <inertia ixx="1.344328e-04" ixy="-1.788649e-08" ixz="2.259163e-05" iyy="1.892619e-04" iyz="9.936937e-07" izz="2.174510e-04"/>
    </inertial>
  </link>
  <!--  Gripper joint -->
  <joint name="gripper" type="prismatic">
    <parent link="link5"/>
    <child link="gripper_link"/>
    <origin rpy="0 0 0" xyz="0.0817 0.021 0.0"/>
    <axis xyz="0 1 0"/>
    <limit effort="1" lower="-0.010" upper="0.019" velocity="4.8"/>
    <dynamics damping="0.1"/>
  </joint>
  <!--  Gripper link -->
  <link name="gripper_link">
    <visual>
      <origin rpy="0 0 0" xyz="0.0 0.0 0"/>
      <geometry>
        <mesh filename="package://open_manipulator_description/meshes/chain_link_grip_l.stl" scale="0.001 0.001 0.001"/>
      </geometry>
      <material name="grey"/>
    </visual>
    <collision>
      <origin rpy="0 0 0" xyz="0.0 0.0 0"/>
      <geometry>
        <mesh filename="package://open_manipulator_description/meshes/chain_link_grip_l.stl" scale="0.001 0.001 0.001"/>
      </geometry>
    </collision>
    <inertial>
      <origin xyz="0 0 0"/>
      <mass value="1.0e-03"/>
      <inertia ixx="1.0e-06" ixy="0.0" ixz="0.0" iyy="1.0e-06" iyz="0.0" izz="1.0e-06"/>
    </inertial>
  </link>
  <!--  Gripper joint sub -->
  <joint name="gripper_sub" type="prismatic">
    <parent link="link5"/>
    <child link="gripper_link_sub"/>
    <origin rpy="0 0 0" xyz="0.0817 -0.021 0"/>
    <axis xyz="0 -1 0"/>
    <limit effort="1" lower="-0.010" upper="0.019" velocity="4.8"/>
    <dynamics damping="0.7"/>
    <mimic joint="gripper" multiplier="1"/>
  </joint>
  <!--  Gripper link sub -->
  <link name="gripper_link_sub">
    <visual>
      <origin rpy="0 0 0" xyz="0.0 -0.0 0"/>
      <geometry>
        <mesh filename="package://open_manipulator_description/meshes/chain_link_grip_r.stl" scale="0.001 0.001 0.001"/>
      </geometry>
      <material name="grey"/>
    </visual>
    <collision>
      <origin rpy="0 0 0" xyz="0.0 -0.0 0"/>
      <geometry>
        <mesh filename="package://open_manipulator_description/meshes/chain_link_grip_r.stl" scale="0.001 0.001 0.001"/>
      </geometry>
    </collision>
    <inertial>
      <origin xyz="0 0 0"/>
      <mass value="1.0e-03"/>
      <inertia ixx="1.0e-06" ixy="0.0" ixz="0.0" iyy="1.0e-06" iyz="0.0" izz="1.0e-06"/>
    </inertial>
  </link>
  <!-- end effector joint -->
  <joint name="end_effector_joint" type="fixed">
    <origin rpy="0 0 0" xyz="0.126 0.0 0.0"/>
    <parent link="link5"/>
    <child link="end_effector_link"/>
  </joint>
  <!-- end effector link -->
  <link name="end_effector_link">
    <visual>
      <origin rpy="0 0 0" xyz="0 0 0"/>
      <geometry>
        <box size="0.01 0.01 0.01"/>
      </geometry>
      <material name="red"/>
    </visual>
    <inertial>
      <origin xyz="0 0 0"/>
      <mass value="1.0e-03"/>
      <inertia ixx="1.0e-06" ixy="0.0" ixz="0.0" iyy="1.0e-06" iyz="0.0" izz="1.0e-06"/>
    </inertial>
  </link>
  <!-- Realsense Camera Joint Position -->
  <!--   <joint name="camera_joint" type="fixed">
    <axis xyz="0 1 0" />
    <origin xyz="0.070 0.032 0.052" rpy="0 0 0"/>
    <parent link="link5"/>
    <child link="camera_link"/>
  </joint>

  <link name="camera_link"/> -->
  <!-- World
  <link name="world"/>

  < World fixed joint>
  <joint name="world_fixed" type="fixed">
    <origin xyz="0 0 0" rpy="0 0 0"/>
    <parent link="world"/>
    <child link="link1"/>
  </joint>
  -->
</robot>
