<?xml version="1.0" ?>
<!-- =================================================================================== -->
<!-- |    This document was autogenerated by xacro from open_manipulator_robot.urdf.xacro | -->
<!-- |    EDITING THIS FILE BY HAND IS NOT RECOMMENDED                                 | -->
<!-- =================================================================================== -->
<!-- Open_Manipulator Chain -->
<!-- Inertial properties updated from ROBOTIS e-Manual specification                    -->
<!-- (platform-openmanipulator-x-specification.pdf, Section 2.3 Inertia).               -->
<!-- For each updated link: mass/CoG/"Inertia Tensor at CENTER OF GRAVITY" from PDF,    -->
<!-- then transformed from Ci frame to URDF link frame via r_urdf=R*r_C, I_urdf=R*I*Rᵀ -->
<!-- Rotations used: link2→R=I; link3→Rz(180°); link4,link5→R_alt=[[0,0,1],[0,-1,0],[1,0,0]] -->
<!-- R_alt maps: Cz→+URDF_x (arm), Cy→-URDF_y, Cx→+URDF_z; I=[Izz,-Iyz,Ixz;-Iyz,Iyy,-Ixy;Ixz,-Ixy,Ixx] -->
<robot name="open_manipulator">
  <material name="black">
    <color rgba="0.0 0.0 0.0 1.0"/>
  </material>
  <material name="white">
    <color rgba="1.0 1.0 1.0 1.0"/>
  </material>
  <material name="red">
    <color rgba="0.8 0.0 0.0 1.0"/>
  </material>
  <material name="blue">
    <color rgba="0.0 0.0 0.8 1.0"/>
  </material>
  <material name="green">
    <color rgba="0.0 0.8 0.0 1.0"/>
  </material>
  <material name="grey">
    <color rgba="0.5 0.5 0.5 1.0"/>
  </material>
  <material name="orange">
    <color rgba="1.0 0.4235294117647059 0.0392156862745098 1.0"/>
  </material>
  <material name="brown">
    <color rgba="0.8705882352941177 0.8117647058823529 0.7647058823529411 1.0"/>
  </material>
  <!-- World -->
  <gazebo reference="world"/>
  <!-- Link1 -->
  <RefLink ref="link1"/>
  <!-- Link2 -->
  <RefLink ref="link2"/>
  <!-- Link3 -->
  <RefLink ref="link3"/>
  <!-- Link4 -->
  <RefLink ref="link4"/>
  <!-- Link5 -->
  <RefLink ref="link5"/>
  <!-- gripper_link -->
  <RefLink ref="gripper_link"/>
  <!-- gripper_link_sub -->
  <RefLink ref="gripper_link_sub"/>
  <!-- end effector link -->
  <gazebo reference="end_effector_link">
    <material>Gazebo/Red</material>
  </gazebo>
  <!-- ros_control plugin -->
  <gazebo>
    <plugin filename="libgazebo_ros_control.so" name="gazebo_ros_control">
      <controlPeriod>0.001</controlPeriod>
      <robotSimType>gazebo_ros_control/DefaultRobotHWSim</robotSimType>
      <legacyModeNS>true</legacyModeNS>
    </plugin>
  </gazebo>
  <gazebo>
    <!-- loading plugin: mimic joints works in gazebo now -->
    <plugin filename="libroboticsgroup_gazebo_mimic_joint_plugin.so" name="gazebo_gripper_ros_control">
      <joint>gripper</joint>
      <mimicJoint>gripper_sub</mimicJoint>
      <multiplier>1.0</multiplier>
      <offset>0.0</offset>
    </plugin>
  </gazebo>
  <!-- camera -->
  <gazebo reference="camera_link">
    <sensor name="intel_realsense_r200" type="camera">
      <update_rate>30.0</update_rate>
      <camera name="head">
        <horizontal_fov>1.02974</horizontal_fov>
        <image>
          <width>1920</width>
          <height>1080</height>
          <format>R8G8B8</format>
        </image>
        <clip>
          <near>0.02</near>
          <far>300</far>
        </clip>
        <noise>
          <type>gaussian</type>
          <!-- Noise is sampled independently per pixel on each frame.
               That pixel's noise value is added to each of its color
               channels, which at that point lie in the range [0,1]. -->
          <mean>0.0</mean>
          <stddev>0.007</stddev>
        </noise>
      </camera>
      <plugin filename="libgazebo_ros_camera.so" name="camera_controller">
        <alwaysOn>true</alwaysOn>
        <updateRate>0.0</updateRate>
        <cameraName>camera/color</cameraName>
        <imageTopicName>image_raw</imageTopicName>
        <cameraInfoTopicName>camera_info</cameraInfoTopicName>
        <frameName>camera_link</frameName>
        <hackBaseline>0.07</hackBaseline>
        <distortionK1>0.0</distortionK1>
        <distortionK2>0.0</distortionK2>
        <distortionK3>0.0</distortionK3>
        <distortionT1>0.0</distortionT1>
        <distortionT2>0.0</distortionT2>
      </plugin>
    </sensor>
  </gazebo>
  <transmission name="tran1">
    <type>transmission_interface/SimpleTransmission</type>
    <joint name="joint1">
      <hardwareInterface>hardware_interface/PositionJointInterface</hardwareInterface>
    </joint>
    <actuator name="motor1">
      <mechanicalReduction>1</mechanicalReduction>
    </actuator>
  </transmission>
  <transmission name="tran2">
    <type>transmission_interface/SimpleTransmission</type>
    <joint name="joint2">
      <hardwareInterface>hardware_interface/PositionJointInterface</hardwareInterface>
    </joint>
    <actuator name="motor2">
      <mechanicalReduction>1</mechanicalReduction>
    </actuator>
  </transmission>
  <transmission name="tran3">
    <type>transmission_interface/SimpleTransmission</type>
    <joint name="joint3">
      <hardwareInterface>hardware_interface/PositionJointInterface</hardwareInterface>
    </joint>
    <actuator name="motor3">
      <mechanicalReduction>1</mechanicalReduction>
    </actuator>
  </transmission>
  <transmission name="tran4">
    <type>transmission_interface/SimpleTransmission</type>
    <joint name="joint4">
      <hardwareInterface>hardware_interface/PositionJointInterface</hardwareInterface>
    </joint>
    <actuator name="motor4">
      <mechanicalReduction>1</mechanicalReduction>
    </actuator>
  </transmission>
  <transmission name="tran5">
    <type>transmission_interface/SimpleTransmission</type>
    <joint name="gripper">
      <hardwareInterface>hardware_interface/EffortJointInterface</hardwareInterface>
    </joint>
    <actuator name="motor5">
      <mechanicalReduction>1</mechanicalReduction>
    </actuator>
  </transmission>
  <transmission name="tran6">
    <type>transmission_interface/SimpleTransmission</type>
    <joint name="gripper_sub">
      <hardwareInterface>hardware_interface/EffortJointInterface</hardwareInterface>
    </joint>
    <actuator name="motor6">
      <mechanicalReduction>1</mechanicalReduction>
    </actuator>
  </transmission>
  <!-- Link 1 -->
  <link name="link1">
    <visual>
      <origin rpy="0 0 0" xyz="0 0 0"/>
      <geometry>
        <mesh filename="package://open_manipulator_description/meshes/chain_link1.stl" scale="0.001 0.001 0.001"/>
      </geometry>
      <material name="grey"/>
    </visual>
    <collision>
      <origin rpy="0 0 0" xyz="0 0 0"/>
      <geometry>
        <mesh filename="package://open_manipulator_description/meshes/chain_link1.stl" scale="0.001 0.001 0.001"/>
      </geometry>
    </collision>
    <inertial>
      <origin xyz="3.0876154e-04 0.0000000e+00 -1.2176461e-04"/>
      <mass value="7.9119962e-02"/>
      <inertia ixx="1.2505234e-05" ixy="0.0" ixz="-1.7855208e-07" iyy="2.1898364e-05" iyz="0.0" izz="1.9267361e-05"/>
    </inertial>
  </link>
  <!-- Joint 1 -->
  <joint name="joint1" type="revolute">
    <parent link="link1"/>
    <child link="link2"/>
    <origin rpy="0 0 0" xyz="0.012 0.0 0.017"/>
    <axis xyz="0 0 1"/>
    <limit effort="1" lower="-2.827433388230814" upper="2.827433388230814" velocity="4.8"/>
    <dynamics damping="0.1"/>
  </joint>
  <!--  Link 2 -->
  <link name="link2">
    <visual>
      <origin rpy="0 0 0" xyz="0 0 0.019"/>
      <geometry>
        <mesh filename="package://open_manipulator_description/meshes/chain_link2.stl" scale="0.001 0.001 0.001"/>
      </geometry>
      <material name="grey"/>
    </visual>
    <collision>
      <origin rpy="0 0 0" xyz="0 0 0.019"/>
      <geometry>
        <mesh filename="package://open_manipulator_description/meshes/chain_link2.stl" scale="0.001 0.001 0.001"/>
      </geometry>
    </collision>
    <!-- Updated from ROBOTIS e-Manual inertial data, using mass/CoG/Inertia Tensor at CENTER OF GRAVITY, transformed from C1 frame to URDF link frame. R = I (no rotation). -->
    <inertial>
      <origin xyz="0.0000000e+00 -5.6914372e-04 2.6565513e-02" rpy="0 0 0"/>
      <mass value="1.0483260e-01"/>
      <inertia ixx="3.3802078e-05" ixy="0.0" ixz="0.0" iyy="2.9569411e-05" iyz="2.2121514e-07" izz="1.7810252e-05"/>
    </inertial>
  </link>
  <!--  Joint 2 -->
  <joint name="joint2" type="revolute">
    <parent link="link2"/>
    <child link="link3"/>
    <origin rpy="0 0 0" xyz="0.0 0.0 0.0595"/>
    <axis xyz="0 1 0"/>
    <limit effort="1" lower="-1.790707812546182" upper="1.5707963267948966" velocity="4.8"/>
    <dynamics damping="0.1"/>
  </joint>
  <!--  Link 3 -->
  <link name="link3">
    <visual>
      <origin rpy="0 0 0" xyz="0 0 0"/>
      <geometry>
        <mesh filename="package://open_manipulator_description/meshes/chain_link3.stl" scale="0.001 0.001 0.001"/>
      </geometry>
      <material name="grey"/>
    </visual>
    <collision>
      <origin rpy="0 0 0" xyz="0 0 0"/>
      <geometry>
        <mesh filename="package://open_manipulator_description/meshes/chain_link3.stl" scale="0.001 0.001 0.001"/>
      </geometry>
    </collision>
    <!-- Updated from ROBOTIS e-Manual inertial data, using mass/CoG/Inertia Tensor at CENTER OF GRAVITY, transformed from C2 frame to URDF link frame. R = Rz(180deg): r_urdf=(-x,-y,z); Ixz->-Ixz, Iyz->-Iyz. -->
    <inertial>
      <origin xyz="9.1617228e-03 4.1915210e-04 1.0599938e-01" rpy="0 0 0"/>
      <mass value="1.4234630e-01"/>
      <inertia ixx="2.3711450e-04" ixy="-2.7513999e-07" ixz="-2.6668982e-05" iyy="2.4488355e-04" iyz="-1.3128636e-06" izz="4.2967059e-05"/>
    </inertial>
  </link>
  <!--  Joint 3 -->
  <joint name="joint3" type="revolute">
    <parent link="link3"/>
    <child link="link4"/>
    <origin rpy="0 0 0" xyz="0.024 0 0.128"/>
    <axis xyz="0 1 0"/>
    <limit effort="1" lower="-0.9424777960769379" upper="1.382300767579509" velocity="4.8"/>
    <dynamics damping="0.1"/>
  </joint>
  <!--  Link 4 -->
  <link name="link4">
    <visual>
      <origin rpy="0 0 0" xyz="0 0 0"/>
      <geometry>
        <mesh filename="package://open_manipulator_description/meshes/chain_link4.stl" scale="0.001 0.001 0.001"/>
      </geometry>
      <material name="grey"/>
    </visual>
    <collision>
      <origin rpy="0 0 0" xyz="0 0 0"/>
      <geometry>
        <mesh filename="package://open_manipulator_description/meshes/chain_link4.stl" scale="0.001 0.001 0.001"/>
      </geometry>
    </collision>
    <!-- Updated from ROBOTIS e-Manual inertial data, using mass/CoG/Inertia Tensor at CENTER OF GRAVITY, transformed from C3 frame to URDF link frame. R = R_alt: C3_z->URDF_x, C3_y->-URDF_y, C3_x->+URDF_z; I_urdf=[Izz,-Iyz,Ixz; -Iyz,Iyy,-Ixy; Ixz,-Ixy,Ixx]. -->
    <inertial>
      <origin xyz="9.3290225e-02 4.4304274e-04 3.6312773e-07" rpy="0 0 0"/>
      <mass value="1.3467049e-01"/>
      <inertia ixx="2.4809204e-05" ixy="-1.2221090e-06" ixz="1.8290300e-09" iyy="1.7818139e-04" iyz="0.0" izz="1.8688812e-04"/>
    </inertial>
  </link>
  <!--  Joint 4 -->
  <joint name="joint4" type="revolute">
    <parent link="link4"/>
    <child link="link5"/>
    <origin rpy="0 0 0" xyz="0.124 0.0 0.0"/>
    <axis xyz="0 1 0"/>
    <limit effort="1" lower="-1.790707812546182" upper="2.0420352248333655" velocity="4.8"/>
    <dynamics damping="0.1"/>
  </joint>
  <!--  Link 5 -->
  <link name="link5">
    <visual>
      <origin rpy="0 0 0" xyz="0 0 0"/>
      <geometry>
        <mesh filename="package://open_manipulator_description/meshes/chain_link5.stl" scale="0.001 0.001 0.001"/>
      </geometry>
      <material name="grey"/>
    </visual>
    <collision>
      <origin rpy="0 0 0" xyz="0 0 0"/>
      <geometry>
        <mesh filename="package://open_manipulator_description/meshes/chain_link5.stl" scale="0.001 0.001 0.001"/>
      </geometry>
    </collision>
    <!-- Updated from ROBOTIS e-Manual inertial data, using mass/CoG/Inertia Tensor at CENTER OF GRAVITY, transformed from C4 frame to URDF link frame. R = R_alt: C4_z->URDF_x, C4_y->-URDF_y, C4_x->+URDF_z; I_urdf=[Izz,-Iyz,Ixz; -Iyz,Iyy,-Ixy; Ixz,-Ixy,Ixx]. -->
    <inertial>
      <origin xyz="6.0472935e-02 7.9503949e-07 6.1273313e-03" rpy="0 0 0"/>
      <mass value="2.3650927e-01"/>
      <inertia ixx="1.7393236e-04" ixy="-1.5305492e-08" ixz="2.2615865e-05" iyy="2.0769766e-04" iyz="-2.2288943e-07" izz="2.6708326e-04"/>
    </inertial>
  </link>
  <!--  Gripper joint -->
  <joint name="gripper" type="prismatic">
    <parent link="link5"/>
    <child link="gripper_link"/>
    <origin rpy="0 0 0" xyz="0.0817 0.021 0.0"/>
    <axis xyz="0 1 0"/>
    <limit effort="1" lower="-0.010" upper="0.019" velocity="4.8"/>
    <dynamics damping="0.1"/>
  </joint>
  <!--  Gripper link -->
  <link name="gripper_link">
    <visual>
      <origin rpy="0 0 0" xyz="0.0 0.0 0"/>
      <geometry>
        <mesh filename="package://open_manipulator_description/meshes/chain_link_grip_l.stl" scale="0.001 0.001 0.001"/>
      </geometry>
      <material name="grey"/>
    </visual>
    <collision>
      <origin rpy="0 0 0" xyz="0.0 0.0 0"/>
      <geometry>
        <mesh filename="package://open_manipulator_description/meshes/chain_link_grip_l.stl" scale="0.001 0.001 0.001"/>
      </geometry>
    </collision>
    <inertial>
      <origin xyz="0 0 0"/>
      <mass value="1.0e-03"/>
      <inertia ixx="1.0e-06" ixy="0.0" ixz="0.0" iyy="1.0e-06" iyz="0.0" izz="1.0e-06"/>
    </inertial>
  </link>
  <!--  Gripper joint sub -->
  <joint name="gripper_sub" type="prismatic">
    <parent link="link5"/>
    <child link="gripper_link_sub"/>
    <origin rpy="0 0 0" xyz="0.0817 -0.021 0"/>
    <axis xyz="0 -1 0"/>
    <limit effort="1" lower="-0.010" upper="0.019" velocity="4.8"/>
    <dynamics damping="0.7"/>
    <mimic joint="gripper" multiplier="1"/>
  </joint>
  <!--  Gripper link sub -->
  <link name="gripper_link_sub">
    <visual>
      <origin rpy="0 0 0" xyz="0.0 -0.0 0"/>
      <geometry>
        <mesh filename="package://open_manipulator_description/meshes/chain_link_grip_r.stl" scale="0.001 0.001 0.001"/>
      </geometry>
      <material name="grey"/>
    </visual>
    <collision>
      <origin rpy="0 0 0" xyz="0.0 -0.0 0"/>
      <geometry>
        <mesh filename="package://open_manipulator_description/meshes/chain_link_grip_r.stl" scale="0.001 0.001 0.001"/>
      </geometry>
    </collision>
    <inertial>
      <origin xyz="0 0 0"/>
      <mass value="1.0e-03"/>
      <inertia ixx="1.0e-06" ixy="0.0" ixz="0.0" iyy="1.0e-06" iyz="0.0" izz="1.0e-06"/>
    </inertial>
  </link>
  <!-- end effector joint -->
  <joint name="end_effector_joint" type="fixed">
    <origin rpy="0 0 0" xyz="0.126 0.0 0.0"/>
    <parent link="link5"/>
    <child link="end_effector_link"/>
  </joint>
  <!-- end effector link -->
  <link name="end_effector_link">
    <visual>
      <origin rpy="0 0 0" xyz="0 0 0"/>
      <geometry>
        <box size="0.01 0.01 0.01"/>
      </geometry>
      <material name="red"/>
    </visual>
    <inertial>
      <origin xyz="0 0 0"/>
      <mass value="1.0e-03"/>
      <inertia ixx="1.0e-06" ixy="0.0" ixz="0.0" iyy="1.0e-06" iyz="0.0" izz="1.0e-06"/>
    </inertial>
  </link>
  <!-- Realsense Camera Joint Position -->
  <!--   <joint name="camera_joint" type="fixed">
    <axis xyz="0 1 0" />
    <origin xyz="0.070 0.032 0.052" rpy="0 0 0"/>
    <parent link="link5"/>
    <child link="camera_link"/>
  </joint>

  <link name="camera_link"/> -->
  <!-- World
  <link name="world"/>

  < World fixed joint>
  <joint name="world_fixed" type="fixed">
    <origin xyz="0 0 0" rpy="0 0 0"/>
    <parent link="world"/>
    <child link="link1"/>
  </joint>
  -->
</robot>
